Workbook

Sheet INSTRUCCIONES
B2: TEST DE ORIENTACIÓN VOCACIONAL
B4: MINEDUC - INVENTARIO DE PREFERENCIAS PROFESIONALES PARA JÓVENES
B8: El instrumento que tienes en tus manos contiene 60 afirmaciones (ítemas) sobre aficiones y preferencias.
B9: Lee muy atentamente cada frase y responde sinceramente a la siguiente pregunta: ¿Hasta qué punto este enunciado me caracteriza?
B10: Elije de la lista desplegable junto a cada ítem, la respuesta que más se ajusta a tus preferencias. Para ello, cuentas con las siguientes opciones:
B11: 1. Totalmente en desacuerdo
B12: 2. En desacuerdo
B13: 3. Es difícil decidir
B14: 4. De acuerdo
B15: 5. Totalmente de acuerdo
B17: A continuación sigue los siguientes pasos:
B19: 1. Lee cuidadosa y completamente estas instrucciones antes de iniciar.
... B25: NOTA DE DESCARGO: La presente es una adaptación virtual del test “Inventario de Preferencias Profesionales para Jóvenes", en su versión editada por el Ministerio de Educación del Ecuador, la misma que se basa en el test elaborado por Ph. D. Mariusz Wołońciej.
C28: ¡Empecemos!
C31: DATOS PERSONALES | E31: INDICACIONES
C32: Apellidos: | D32: JARAMILLO CAICEDO | E32: USA MAYÚSCULAS
C33: Nombres: | D33: RUBÉN PATRICIO | E33: USA MAYÚSCULAS
C34: Curso: | D34: 3º BGU | E34: LISTA DESPLEGABLE
C35: Paralelo: | D35: A | E35: USA MAYÚSCULAS
C36: Edad: | D36: 19 | E36: SÓLO NÚMEROS
C37: Género: | D37: MASCULINO | E37: LISTA DESPLEGABLE
C38: Fecha: | D38: 44194 | E38: DD/MM/AA. Ejemplo: 31/10/17
XEY1048548: 10º EGB | XEZ1048548: A | XFA1048548: 42736 | XFB1048548: FÍSICO-MATEMÁTICO | XFC1048548: MASCULINO
XEY1048549: 1º BGU | XEZ1048549: B | XFA1048549: 46752 | XFB1048549: QUÍMICO-BIÓLOGO | XFC1048549: FEMENINO
XEY1048550: 2º BGU | XEZ1048550: C | XFB1048550: CIENCIAS SOCIALES | XFC1048550: OTRO
XEY1048551: 3º BGU

Sheet ENCUESTA
A1: ENCUESTA
A3: 1.- | B3: ¿Cuáles son tus tres profesiones de mayor preferencia? Escríbelas en orden de preferencia:
B4: 1) | C4: MEDICINA
B5: 2) | C5: SISTEMAS
B6: 3) | C6: ELECTRICIDAD
A8: 2.- | B8: ¿Cuáles son las tres profesiones de menor preferencia? Escríbelas en orden:
B9: 1) | C9: EDUCACION
B10: 2) | C10: PSICOLOGIA
B11: 3) | C11: EDUCACION FISICA
A13: 3.- | B13: ¿Cuál es el nivel de estudios de tu madre o cuidadora principal?
B14: * | C14: ¿Qué profesión ejerce tu madre o cuidadora principal? | D14: CAJERA
A16: 4.- | B16: ¿Cuál es el nivel de estudios de tu padre o cuidador principal?
B17: * | C17: ¿Qué profesión ejerce tu padre o cuidador principal? | D17: PERIODISTA
A19: 5.- | B19: ¿Qué tipo de actividades realizas en tu tiempo libre? Escribe tres en orden de preferencia:
B20: 1) | C20: NADA
B21: 2) | C21: JUEGOS
B22: 3) | C22: FORNITE
A24: 6.- | B24: ¿Qué es para ti el éxito profesional? Escribe tres características de una persona que es exitosa en su vida laboral:
B25: 1) | C25: NA
B26: 2) | C26: NA
B27: 3) | C27: NA
A29: 7.- | B29: ¿Qué tan importante es para ti lograr el éxito en tus estudios y en tu vida laboral? ¿Por qué?
B30: 1) | C30: NA
B31: 2) | C31: NA
B32: 3) | C32: NA
XFC1048554: Ciencias Sociales
XFC1048555: Físico - Matemático
XFC1048556: Químico - Biológo
XFC1048558: Totalmente decidido/a
XFC1048559: Es a lo que más me inclino, pero tengo algunas dudas
XFC1048560: No estoy muy seguro/a
XFC1048561: Tengo muchas dudas
XFC1048563: No lo sé
XFC1048564: Educación Básica
XFC1048565: Bachillerato
XFC1048566: Tercer nivel (tecnología, licenciatura o ingeniería)
XFC1048567: Cuarto nivel (maestría, doctorado, post-doctorado)

Sheet CUESTIONARIO
A1: No. | B1: ITEM | C1: RESPUESTA
A2: 1 | B2: Me gusta realizar pequeñas reparaciones de equipos electrodomésticos. | C2: 2. En desacuerdo
A3: 2 | B3: El trabajo científico me parece muy interesante. | C3: 3. Es difícil decidir
A4: 3 | B4: Sé tocar un instrumento musical o me gustaría aprender. | C4: 4. De acuerdo
A5: 4 | B5: Me gustaría cuidar personas con enfermedades mentales. | C5: 2. En desacuerdo
A6: 5 | B6: Me siento bien y me las arreglo cuando tengo que organizar el trabajo de mis compañeros y compañeras. Fijarles tareas y comprobar si han sido realizadas. | C6: 2. En desacuerdo
A7: 6 | B7: Me gusta llevar mis cuadernos de manera ordenada y limpia. | C7: 4. De acuerdo
A8: 7 | B8: Me gustaría trabajar en el servicio técnico de una empresa. | C8: 3. Es difícil decidir
A9: 8 | B9: Me gustaría trabajar en un centro de investigación o en un laboratorio. | C9: 2. En desacuerdo
A10: 9 | B10: En el futuro me gustaría escribir poemas, guiones de películas o de juegos de video. | C10: 4. De acuerdo
A11: 10 | B11: Me gusta mucho participar en organizaciones no gubernamentales como la Cruz Roja o una organización de jóvenes exploradores. | C11: 3. Es difícil decidir
A12: 11 | B12: A veces en la escuela soluciono conflictos de mis compañeros y compañeras. | C12: 2. En desacuerdo
A13: 12 | B13: En mi puesto de trabajo me gustaría trabajar según normas estrictamente definidas. | C13: 2. En desacuerdo
... A61: 60 | B61: Me gusta organizar mi trabajo día a día y para la semana. | C61: 3. Es difícil decidir
XFD1048572: 1. Totalmente en desacuerdo
XFD1048573: 2. En desacuerdo
XFD1048574: 3. Es difícil decidir
XFD1048575: 4. De acuerdo
XFD1048576: 5. Totalmente de acuerdo

Sheet fórmulas
A1: No. | B1: Puntaje neto | D1: SUMA Puntaje neto | G1: STEN MUJERES | H1: STEN HOMBRES | I1: INTENSIDAD GÉNERO | M1: CONSISTENCIA MUJERES | N1: CONSISTENCIA MUJERES | O1: INTERPRETACIÓN CONSISTENCIA MUJERES | P1: INTERPRETACIÓN CONSISTENCIA HOMBRES
A2: 1 | B2: =IF(CUESTIONARIO!C2="1. Totalmente en desacuerdo",(1),IF(CUESTIONARIO!C2="2. En desacuerdo",(2),IF(CUESTIONARIO!C2="3. Es difícil decidir",(3),IF(CUESTIONARIO!C2="4. De acuerdo",(4),IF(CUESTIONARIO!C2="5. Totalmente de acuerdo",(5)))))) -> 2 | D2: REALISTA | E2: =SUM(B2,B14,B20,B26,B32,B38,B44,B50,B56) -> 30 | G2: =IF(E2>46,(10),IF(E2>44,(9),IF(E2>41,(8),(IF(E2>38,(7),IF(E2>34,(6),IF(E2>29,(5),IF(E2>25,(4),IF(E2>19,(3),IF(E2>13,(2),IF(E2>9,(1)))))))))))) -> 5 | H2: =IF(E2>48,(10),IF(E2>46,(9),IF(E2>44,(8),(IF(E2>42,(7),IF(E2>39,(6),IF(E2>36,(5),IF(E2>32,(4),IF(E2>28,(3),IF(E2>23,(2),IF(E2>10,(1)))))))))))) -> 3 | I2: =IF(INSTRUCCIONES!D37="FEMENINO",fórmulas!G2,IF(INSTRUCCIONES!D37="MASCULINO",fórmulas!H2)) -> 3 | L2: REALISTA - INVESTIGADORA | M2: =G2-G3 -> 3 | N2: =H2-H3 -> 1 | O2: =IF(OR(M2>6,M2<-6),"Baja",IF(OR(M2>3,M2<-3),"Media",IF(OR(M2>=0,M2<=0),"Alta"))) -> Alta | P2: =IF(OR(N2>6,N2<-6),"Baja",IF(OR(N2>3,N2<-3),"Media",IF(OR(N2>=0,N2<=0),"Alta"))) -> Alta
A3: 2 | B3: =IF(CUESTIONARIO!C3="1. Totalmente en desacuerdo",(1),IF(CUESTIONARIO!C3="2. En desacuerdo",(2),IF(CUESTIONARIO!C3="3. Es difícil decidir",(3),IF(CUESTIONARIO!C3="4. De acuerdo",(4),IF(CUESTIONARIO!C3="5. Totalmente de acuerdo",(5)))))) -> 3 | D3: INVESTIGADORA | E3: =SUM(B3,B15,B21,B27,B33,B39,B45,B51,B57) -> 23 | G3: =IF(E3>48,(10),IF(E3>46,(9),IF(E3>44,(8),(IF(E3>41,(7),IF(E3>37,(6),IF(E3>33,(5),IF(E3>28,(4),IF(E3>23,(3),IF(E3>17,(2),IF(E3>9,(1)))))))))))) -> 2 | H3: =IF(E3>48,(10),IF(E3>46,(9),IF(E3>44,(8),(IF(E3>41,(7),IF(E3>37,(6),IF(E3>33,(5),IF(E3>28,(4),IF(E3>23,(3),IF(E3>17,(2),IF(E3>9,(1)))))))))))) -> 2 | I3: =IF(INSTRUCCIONES!D37="FEMENINO",fórmulas!G3,IF(INSTRUCCIONES!D37="MASCULINO",fórmulas!H3)) -> 2 | L3: INVESTIGADORA - ARTISTICA | M3: =G3-G4 -> 0 | N3: =H3-H4 -> 0 | O3: =IF(OR(M3>6,M3<-6),"Baja",IF(OR(M3>3,M3<-3),"Media",IF(OR(M3>=0,M3<=0),"Alta"))) -> Alta | P3: =IF(OR(N3>6,N3<-6),"Baja",IF(OR(N3>3,N3<-3),"Media",IF(OR(N3>=0,N3<=0),"Alta"))) -> Alta
A4: 3 | B4: =IF(CUESTIONARIO!C4="1. Totalmente en desacuerdo",(1),IF(CUESTIONARIO!C4="2. En desacuerdo",(2),IF(CUESTIONARIO!C4="3. Es difícil decidir",(3),IF(CUESTIONARIO!C4="4. De acuerdo",(4),IF(CUESTIONARIO!C4="5. Totalmente de acuerdo",(5)))))) -> 4 | D4: ARTISTICA | E4: =SUM(B4,B16,B22,B28,B34,B40,B46,B52,B58) -> 20 | G4: =IF(E4>47,(10),IF(E4>45,(9),IF(E4>42,(8),(IF(E4>39,(7),IF(E4>35,(6),IF(E4>31,(5),IF(E4>27,(4),IF(E4>22,(3),IF(E4>16,(2),IF(E4>9,(1)))))))))))) -> 2 | H4: =IF(E4>47,(10),IF(E4>45,(9),IF(E4>42,(8),(IF(E4>39,(7),IF(E4>35,(6),IF(E4>31,(5),IF(E4>27,(4),IF(E4>22,(3),IF(E4>16,(2),IF(E4>9,(1)))))))))))) -> 2 | I4: =IF(INSTRUCCIONES!D37="FEMENINO",fórmulas!G4,IF(INSTRUCCIONES!D37="MASCULINO",fórmulas!H4)) -> 2 | L4: ARTISTICA - SOCIAL | M4: =G4-G5 -> -1 | N4: =H4-H5 -> -2 | O4: =IF(OR(M4>6,M4<-6),"Baja",IF(OR(M4>3,M4<-3),"Media",IF(OR(M4>=0,M4<=0),"Alta"))) -> Alta | P4: =IF(OR(N4>6,N4<-6),"Baja",IF(OR(N4>3,N4<-3),"Media",IF(OR(N4>=0,N4<=0),"Alta"))) -> Alta
A5: 4 | B5: =IF(CUESTIONARIO!C5="1. Totalmente en desacuerdo",(1),IF(CUESTIONARIO!C5="2. En desacuerdo",(2),IF(CUESTIONARIO!C5="3. Es difícil decidir",(3),IF(CUESTIONARIO!C5="4. De acuerdo",(4),IF(CUESTIONARIO!C5="5. Totalmente de acuerdo",(5)))))) -> 2 | D5: SOCIAL | E5: =SUM(B5,B17,B23,B29,B35,B41,B47,B53,B59) -> 26 | G5: =IF(E5>48,(10),IF(E5>46,(9),IF(E5>44,(8),(IF(E5>41,(7),IF(E5>37,(6),IF(E5>33,(5),IF(E5>28,(4),IF(E5>23,(3),IF(E5>17,(2),IF(E5>9,(1)))))))))))) -> 3 | H5: =IF(E5>44,(10),IF(E5>42,(9),IF(E5>39,(8),(IF(E5>36,(7),IF(E5>32,(6),IF(E5>28,(5),IF(E5>24,(4),IF(E5>20,(3),IF(E5>15,(2),IF(E5>9,(1)))))))))))) -> 4 | I5: =IF(INSTRUCCIONES!D37="FEMENINO",fórmulas!G5,IF(INSTRUCCIONES!D37="MASCULINO",fórmulas!H5)) -> 4 | L5: SOCIAL - EMPRENDEDORA | M5: =G5-G6 -> 1 | N5: =H5-H6 -> 3 | O5: =IF(OR(M5>6,M5<-6),"Baja",IF(OR(M5>3,M5<-3),"Media",IF(OR(M5>=0,M5<=0),"Alta"))) -> Alta | P5: =IF(OR(N5>6,N5<-6),"Baja",IF(OR(N5>3,N5<-3),"Media",IF(OR(N5>=0,N5<=0),"Alta"))) -> Alta
A6: 5 | B6: =IF(CUESTIONARIO!C6="1. Totalmente en desacuerdo",(1),IF(CUESTIONARIO!C6="2. En desacuerdo",(2),IF(CUESTIONARIO!C6="3. Es difícil decidir",(3),IF(CUESTIONARIO!C6="4. De acuerdo",(4),IF(CUESTIONARIO!C6="5. Totalmente de acuerdo",(5)))))) -> 2 | D6: EMPRENDEDORA | E6: =SUM(B6,B18,B24,B30,B36,B42,B48,B54,B60) -> 20 | G6: =IF(E6>47,(10),IF(E6>45,(9),IF(E6>42,(8),(IF(E6>39,(7),IF(E6>35,(6),IF(E6>31,(5),IF(E6>27,(4),IF(E6>22,(3),IF(E6>16,(2),IF(E6>9,(1)))))))))))) -> 2 | H6: =IF(E6>45,(10),IF(E6>43,(9),IF(E6>41,(8),(IF(E6>38,(7),IF(E6>35,(6),IF(E6>32,(5),IF(E6>29,(4),IF(E6>25,(3),IF(E6>21,(2),IF(E6>9,(1)))))))))))) -> 1 | I6: =IF(INSTRUCCIONES!D37="FEMENINO",fórmulas!G6,IF(INSTRUCCIONES!D37="MASCULINO",fórmulas!H6)) -> 1 | L6: EMPRENDEDORA - CONVENCIONAL | M6: =G6-G7 -> -2 | N6: =H6-H7 -> -2 | O6: =IF(OR(M6>6,M6<-6),"Baja",IF(OR(M6>3,M6<-3),"Media",IF(OR(M6>=0,M6<=0),"Alta"))) -> Alta | P6: =IF(OR(N6>6,N6<-6),"Baja",IF(OR(N6>3,N6<-3),"Media",IF(OR(N6>=0,N6<=0),"Alta"))) -> Alta
A7: 6 | B7: =IF(CUESTIONARIO!C7="1. Totalmente en desacuerdo",(1),IF(CUESTIONARIO!C7="2. En desacuerdo",(2),IF(CUESTIONARIO!C7="3. Es difícil decidir",(3),IF(CUESTIONARIO!C7="4. De acuerdo",(4),IF(CUESTIONARIO!C7="5. Totalmente de acuerdo",(5)))))) -> 4 | D7: CONVENCIONAL | E7: =SUM(B7,B19,B25,B31,B37,B43,B49,B55,B61) -> 33 | G7: =IF(E7>48,(10),IF(E7>46,(9),IF(E7>44,(8),(IF(E7>41,(7),IF(E7>37,(6),IF(E7>33,(5),IF(E7>28,(4),IF(E7>23,(3),IF(E7>17,(2),IF(E7>9,(1)))))))))))) -> 4 | H7: =IF(E7>49,(10),IF(E7>47,(9),IF(E7>46,(8),(IF(E7>43,(7),IF(E7>40,(6),IF(E7>37,(5),IF(E7>34,(4),IF(E7>30,(3),IF(E7>25,(2),IF(E7>9,(1)))))))))))) -> 3 | I7: =IF(INSTRUCCIONES!D37="FEMENINO",fórmulas!G7,IF(INSTRUCCIONES!D37="MASCULINO",fórmulas!H7)) -> 3 | L7: CONVENCIONAL - REALISTA | M7: =G7-G2 -> -1 | N7: =H7-H2 -> 0 | O7: =IF(OR(M7>6,M7<-6),"Baja",IF(OR(M7>3,M7<-3),"Media",IF(OR(M7>=0,M7<=0),"Alta"))) -> Alta | P7: =IF(OR(N7>6,N7<-6),"Baja",IF(OR(N7>3,N7<-3),"Media",IF(OR(N7>=0,N7<=0),"Alta"))) -> Alta
A8: 7 | B8: =IF(CUESTIONARIO!C8="1. Totalmente en desacuerdo",(1),IF(CUESTIONARIO!C8="2. En desacuerdo",(2),IF(CUESTIONARIO!C8="3. Es difícil decidir",(3),IF(CUESTIONARIO!C8="4. De acuerdo",(4),IF(CUESTIONARIO!C8="5. Totalmente de acuerdo",(5)))))) -> 3 | D8: INTENSIDAD (TOTAL DIMENSIONES) | E8: =SUM(E2:E7) -> 152 | G8: =IF(E8>276,(10),IF(E8>267,(9),IF(E8>261,(8),(IF(E8>232,(7),IF(E8>218,(6),IF(E8>203,(5),IF(E8>188,(4),IF(E8>174,(3),IF(E8>159,(2),IF(E8>59,(1)))))))))))) -> 1 | H8: =IF(E8>282,(10),IF(E8>266,(9),IF(E8>251,(8),(IF(E8>235,(7),IF(E8>219,(6),IF(E8>204,(5),IF(E8>189,(4),IF(E8>173,(3),IF(E8>157,(2),IF(E8>59,(1)))))))))))) -> 1 | I8: =IF(INSTRUCCIONES!D37="FEMENINO",fórmulas!G8,IF(INSTRUCCIONES!D37="MASCULINO",fórmulas!H8)) -> 1
A9: 8 | B9: =IF(CUESTIONARIO!C9="1. Totalmente en desacuerdo",(1),IF(CUESTIONARIO!C9="2. En desacuerdo",(2),IF(CUESTIONARIO!C9="3. Es difícil decidir",(3),IF(CUESTIONARIO!C9="4. De acuerdo",(4),IF(CUESTIONARIO!C9="5. Totalmente de acuerdo",(5)))))) -> 2
A10: 9 | B10: =IF(CUESTIONARIO!C10="1. Totalmente en desacuerdo",(1),IF(CUESTIONARIO!C10="2. En desacuerdo",(2),IF(CUESTIONARIO!C10="3. Es difícil decidir",(3),IF(CUESTIONARIO!C10="4. De acuerdo",(4),IF(CUESTIONARIO!C10="5. Totalmente de acuerdo",(5)))))) -> 4
A11: 10 | B11: =IF(CUESTIONARIO!C11="1. Totalmente en desacuerdo",(1),IF(CUESTIONARIO!C11="2. En desacuerdo",(2),IF(CUESTIONARIO!C11="3. Es difícil decidir",(3),IF(CUESTIONARIO!C11="4. De acuerdo",(4),IF(CUESTIONARIO!C11="5. Totalmente de acuerdo",(5)))))) -> 3 | D11: DIFERENCIACIÓN
A12: 11 | B12: =IF(CUESTIONARIO!C12="1. Totalmente en desacuerdo",(1),IF(CUESTIONARIO!C12="2. En desacuerdo",(2),IF(CUESTIONARIO!C12="3. Es difícil decidir",(3),IF(CUESTIONARIO!C12="4. De acuerdo",(4),IF(CUESTIONARIO!C12="5. Totalmente de acuerdo",(5)))))) -> 2 | E12: REALISTA | F12: INVESTIGADORA | G12: ARTISTICA | H12: SOCIAL | I12: EMPRENDEDORA | J12: CONVENCIONAL
A13: 12 | B13: =IF(CUESTIONARIO!C13="1. Totalmente en desacuerdo",(1),IF(CUESTIONARIO!C13="2. En desacuerdo",(2),IF(CUESTIONARIO!C13="3. Es difícil decidir",(3),IF(CUESTIONARIO!C13="4. De acuerdo",(4),IF(CUESTIONARIO!C13="5. Totalmente de acuerdo",(5)))))) -> 2 | D13: REALISTA | E13: =E2-E2 -> 0 | F13: =E3-E2 -> -7 | G13: =E4-E2 -> -10 | H13: =E5-E2 -> -4 | I13: =E6-E2 -> -10 | J13: =E7-E2 -> 3
A14: 13 | B14: =IF(CUESTIONARIO!C14="1. Totalmente en desacuerdo",(1),IF(CUESTIONARIO!C14="2. En desacuerdo",(2),IF(CUESTIONARIO!C14="3. Es difícil decidir",(3),IF(CUESTIONARIO!C14="4. De acuerdo",(4),IF(CUESTIONARIO!C14="5. Totalmente de acuerdo",(5)))))) -> 3 | D14: INVESTIGADORA | E14: =E2-E3 -> 7 | F14: =E3-E3 -> 0 | G14: =E4-E3 -> -3 | H14: =E5-E3 -> 3 | I14: =E6-E3 -> -3 | J14: =E7-E3 -> 10
A15: 14 | B15: =IF(CUESTIONARIO!C15="1. Totalmente en desacuerdo",(1),IF(CUESTIONARIO!C15="2. En desacuerdo",(2),IF(CUESTIONARIO!C15="3. Es difícil decidir",(3),IF(CUESTIONARIO!C15="4. De acuerdo",(4),IF(CUESTIONARIO!C15="5. Totalmente de acuerdo",(5)))))) -> 2 | D15: ARTISTICA | E15: =E2-E4 -> 10 | F15: =E3-E4 -> 3 | G15: =E4-E4 -> 0 | H15: =E5-E4 -> 6 | I15: =E6-E4 -> 0 | J15: =E7-E4 -> 13
A16: 15 | B16: =IF(CUESTIONARIO!C16="1. Totalmente en desacuerdo",(1),IF(CUESTIONARIO!C16="2. En desacuerdo",(2),IF(CUESTIONARIO!C16="3. Es difícil decidir",(3),IF(CUESTIONARIO!C16="4. De acuerdo",(4),IF(CUESTIONARIO!C16="5. Totalmente de acuerdo",(5)))))) -> 2 | D16: SOCIAL | E16: =E2-E5 -> 4 | F16: =E3-E5 -> -3 | G16: =E4-E5 -> -6 | H16: =E5-E5 -> 0 | I16: =E6-E5 -> -6 | J16: =E7-E5 -> 7
A17: 16 | B17: =IF(CUESTIONARIO!C17="1. Totalmente en desacuerdo",(1),IF(CUESTIONARIO!C17="2. En desacuerdo",(2),IF(CUESTIONARIO!C17="3. Es difícil decidir",(3),IF(CUESTIONARIO!C17="4. De acuerdo",(4),IF(CUESTIONARIO!C17="5. Totalmente de acuerdo",(5)))))) -> 2 | D17: EMPRENDEDORA | E17: =E2-E6 -> 10 | F17: =E3-E6 -> 3 | G17: =E4-E6 -> 0 | H17: =E5-E6 -> 6 | I17: =E6-E6 -> 0 | J17: =E7-E6 -> 13
A18: 17 | B18: =IF(CUESTIONARIO!C18="1. Totalmente en desacuerdo",(1),IF(CUESTIONARIO!C18="2. En desacuerdo",(2),IF(CUESTIONARIO!C18="3. Es difícil decidir",(3),IF(CUESTIONARIO!C18="4. De acuerdo",(4),IF(CUESTIONARIO!C18="5. Totalmente de acuerdo",(5)))))) -> 3 | D18: CONVENCIONAL | E18: =E2-E7 -> -3 | F18: =E3-E7 -> -10 | G18: =E4-E7 -> -13 | H18: =E5-E7 -> -7 | I18: =E6-E7 -> -13 | J18: =E7-E7 -> 0
A19: 18 | B19: =IF(CUESTIONARIO!C19="1. Totalmente en desacuerdo",(1),IF(CUESTIONARIO!C19="2. En desacuerdo",(2),IF(CUESTIONARIO!C19="3. Es difícil decidir",(3),IF(CUESTIONARIO!C19="4. De acuerdo",(4),IF(CUESTIONARIO!C19="5. Totalmente de acuerdo",(5)))))) -> 4
A20: 19 | B20: =IF(CUESTIONARIO!C20="1. Totalmente en desacuerdo",(1),IF(CUESTIONARIO!C20="2. En desacuerdo",(2),IF(CUESTIONARIO!C20="3. Es difícil decidir",(3),IF(CUESTIONARIO!C20="4. De acuerdo",(4),IF(CUESTIONARIO!C20="5. Totalmente de acuerdo",(5)))))) -> 2 | D20: STEN DIFERENCIACIÓN MUJERES
A21: 20 | B21: =IF(CUESTIONARIO!C21="1. Totalmente en desacuerdo",(1),IF(CUESTIONARIO!C21="2. En desacuerdo",(2),IF(CUESTIONARIO!C21="3. Es difícil decidir",(3),IF(CUESTIONARIO!C21="4. De acuerdo",(4),IF(CUESTIONARIO!C21="5. Totalmente de acuerdo",(5)))))) -> 3 | E21: REALISTA | F21: INVESTIGADORA | G21: ARTISTICA | H21: SOCIAL | I21: EMPRENDEDORA | J21: CONVENCIONAL
A22: 21 | B22: =IF(CUESTIONARIO!C22="1. Totalmente en desacuerdo",(1),IF(CUESTIONARIO!C22="2. En desacuerdo",(2),IF(CUESTIONARIO!C22="3. Es difícil decidir",(3),IF(CUESTIONARIO!C22="4. De acuerdo",(4),IF(CUESTIONARIO!C22="5. Totalmente de acuerdo",(5)))))) -> 4 | D22: REALISTA | E22: =IF(E13>34,(10),IF(E13>27,(9),IF(E13>21,(8),(IF(E13>15,(7),IF(E13>11,(6),IF(E13>9,(5),IF(E13>7,(4),IF(E13>5,(3),IF(E13>4,(2),IF(E13>0,(1),"-"))))))))))) -> - | F22: =IF(F13>34,(10),IF(F13>27,(9),IF(F13>21,(8),(IF(F13>15,(7),IF(F13>11,(6),IF(F13>9,(5),IF(F13>7,(4),IF(F13>5,(3),IF(F13>4,(2),IF(F13>0,(1),"-"))))))))))) -> - | G22: =IF(G13>34,(10),IF(G13>27,(9),IF(G13>21,(8),(IF(G13>15,(7),IF(G13>11,(6),IF(G13>9,(5),IF(G13>7,(4),IF(G13>5,(3),IF(G13>4,(2),IF(G13>0,(1),"-"))))))))))) -> - | H22: =IF(H13>34,(10),IF(H13>27,(9),IF(H13>21,(8),(IF(H13>15,(7),IF(H13>11,(6),IF(H13>9,(5),IF(H13>7,(4),IF(H13>5,(3),IF(H13>4,(2),IF(H13>0,(1),"-"))))))))))) -> - | I22: =IF(I13>34,(10),IF(I13>27,(9),IF(I13>21,(8),(IF(I13>15,(7),IF(I13>11,(6),IF(I13>9,(5),IF(I13>7,(4),IF(I13>5,(3),IF(I13>4,(2),IF(I13>0,(1),"-"))))))))))) -> - | J22: =IF(J13>34,(10),IF(J13>27,(9),IF(J13>21,(8),(IF(J13>15,(7),IF(J13>11,(6),IF(J13>9,(5),IF(J13>7,(4),IF(J13>5,(3),IF(J13>4,(2),IF(J13>0,(1),"-"))))))))))) -> 1
A23: 22 | B23: =IF(CUESTIONARIO!C23="1. Totalmente en desacuerdo",(1),IF(CUESTIONARIO!C23="2. En desacuerdo",(2),IF(CUESTIONARIO!C23="3. Es difícil decidir",(3),IF(CUESTIONARIO!C23="4. De acuerdo",(4),IF(CUESTIONARIO!C23="5. Totalmente de acuerdo",(5)))))) -> 4 | D23: INVESTIGADORA | E23: =IF(E14>34,(10),IF(E14>27,(9),IF(E14>21,(8),(IF(E14>15,(7),IF(E14>11,(6),IF(E14>9,(5),IF(E14>7,(4),IF(E14>5,(3),IF(E14>4,(2),IF(E14>0,(1),"-"))))))))))) -> 3 | F23: =IF(F14>34,(10),IF(F14>27,(9),IF(F14>21,(8),(IF(F14>15,(7),IF(F14>11,(6),IF(F14>9,(5),IF(F14>7,(4),IF(F14>5,(3),IF(F14>4,(2),IF(F14>0,(1),"-"))))))))))) -> - | G23: =IF(G14>34,(10),IF(G14>27,(9),IF(G14>21,(8),(IF(G14>15,(7),IF(G14>11,(6),IF(G14>9,(5),IF(G14>7,(4),IF(G14>5,(3),IF(G14>4,(2),IF(G14>0,(1),"-"))))))))))) -> - | H23: =IF(H14>34,(10),IF(H14>27,(9),IF(H14>21,(8),(IF(H14>15,(7),IF(H14>11,(6),IF(H14>9,(5),IF(H14>7,(4),IF(H14>5,(3),IF(H14>4,(2),IF(H14>0,(1),"-"))))))))))) -> 1 | I23: =IF(I14>34,(10),IF(I14>27,(9),IF(I14>21,(8),(IF(I14>15,(7),IF(I14>11,(6),IF(I14>9,(5),IF(I14>7,(4),IF(I14>5,(3),IF(I14>4,(2),IF(I14>0,(1),"-"))))))))))) -> - | J23: =IF(J14>34,(10),IF(J14>27,(9),IF(J14>21,(8),(IF(J14>15,(7),IF(J14>11,(6),IF(J14>9,(5),IF(J14>7,(4),IF(J14>5,(3),IF(J14>4,(2),IF(J14>0,(1),"-"))))))))))) -> 5
A24: 23 | B24: =IF(CUESTIONARIO!C24="1. Totalmente en desacuerdo",(1),IF(CUESTIONARIO!C24="2. En desacuerdo",(2),IF(CUESTIONARIO!C24="3. Es difícil decidir",(3),IF(CUESTIONARIO!C24="4. De acuerdo",(4),IF(CUESTIONARIO!C24="5. Totalmente de acuerdo",(5)))))) -> 2 | D24: ARTISTICA | E24: =IF(E15>34,(10),IF(E15>27,(9),IF(E15>21,(8),(IF(E15>15,(7),IF(E15>11,(6),IF(E15>9,(5),IF(E15>7,(4),IF(E15>5,(3),IF(E15>4,(2),IF(E15>0,(1),"-"))))))))))) -> 5 | F24: =IF(F15>34,(10),IF(F15>27,(9),IF(F15>21,(8),(IF(F15>15,(7),IF(F15>11,(6),IF(F15>9,(5),IF(F15>7,(4),IF(F15>5,(3),IF(F15>4,(2),IF(F15>0,(1),"-"))))))))))) -> 1 | G24: =IF(G15>34,(10),IF(G15>27,(9),IF(G15>21,(8),(IF(G15>15,(7),IF(G15>11,(6),IF(G15>9,(5),IF(G15>7,(4),IF(G15>5,(3),IF(G15>4,(2),IF(G15>0,(1),"-"))))))))))) -> - | H24: =IF(H15>34,(10),IF(H15>27,(9),IF(H15>21,(8),(IF(H15>15,(7),IF(H15>11,(6),IF(H15>9,(5),IF(H15>7,(4),IF(H15>5,(3),IF(H15>4,(2),IF(H15>0,(1),"-"))))))))))) -> 3 | I24: =IF(I15>34,(10),IF(I15>27,(9),IF(I15>21,(8),(IF(I15>15,(7),IF(I15>11,(6),IF(I15>9,(5),IF(I15>7,(4),IF(I15>5,(3),IF(I15>4,(2),IF(I15>0,(1),"-"))))))))))) -> - | J24: =IF(J15>34,(10),IF(J15>27,(9),IF(J15>21,(8),(IF(J15>15,(7),IF(J15>11,(6),IF(J15>9,(5),IF(J15>7,(4),IF(J15>5,(3),IF(J15>4,(2),IF(J15>0,(1),"-"))))))))))) -> 6
A25: 24 | B25: =IF(CUESTIONARIO!C25="1. Totalmente en desacuerdo",(1),IF(CUESTIONARIO!C25="2. En desacuerdo",(2),IF(CUESTIONARIO!C25="3. Es difícil decidir",(3),IF(CUESTIONARIO!C25="4. De acuerdo",(4),IF(CUESTIONARIO!C25="5. Totalmente de acuerdo",(5)))))) -> 4 | D25: SOCIAL | E25: =IF(E16>34,(10),IF(E16>27,(9),IF(E16>21,(8),(IF(E16>15,(7),IF(E16>11,(6),IF(E16>9,(5),IF(E16>7,(4),IF(E16>5,(3),IF(E16>4,(2),IF(E16>0,(1),"-"))))))))))) -> 1 | F25: =IF(F16>34,(10),IF(F16>27,(9),IF(F16>21,(8),(IF(F16>15,(7),IF(F16>11,(6),IF(F16>9,(5),IF(F16>7,(4),IF(F16>5,(3),IF(F16>4,(2),IF(F16>0,(1),"-"))))))))))) -> - | G25: =IF(G16>34,(10),IF(G16>27,(9),IF(G16>21,(8),(IF(G16>15,(7),IF(G16>11,(6),IF(G16>9,(5),IF(G16>7,(4),IF(G16>5,(3),IF(G16>4,(2),IF(G16>0,(1),"-"))))))))))) -> - | H25: =IF(H16>34,(10),IF(H16>27,(9),IF(H16>21,(8),(IF(H16>15,(7),IF(H16>11,(6),IF(H16>9,(5),IF(H16>7,(4),IF(H16>5,(3),IF(H16>4,(2),IF(H16>0,(1),"-"))))))))))) -> - | I25: =IF(I16>34,(10),IF(I16>27,(9),IF(I16>21,(8),(IF(I16>15,(7),IF(I16>11,(6),IF(I16>9,(5),IF(I16>7,(4),IF(I16>5,(3),IF(I16>4,(2),IF(I16>0,(1),"-"))))))))))) -> - | J25: =IF(J16>34,(10),IF(J16>27,(9),IF(J16>21,(8),(IF(J16>15,(7),IF(J16>11,(6),IF(J16>9,(5),IF(J16>7,(4),IF(J16>5,(3),IF(J16>4,(2),IF(J16>0,(1),"-"))))))))))) -> 3
A26: 25 | B26: =IF(CUESTIONARIO!C26="1. Totalmente en desacuerdo",(1),IF(CUESTIONARIO!C26="2. En desacuerdo",(2),IF(CUESTIONARIO!C26="3. Es difícil decidir",(3),IF(CUESTIONARIO!C26="4. De acuerdo",(4),IF(CUESTIONARIO!C26="5. Totalmente de acuerdo",(5)))))) -> 4 | D26: EMPRENDEDORA | E26: =IF(E17>34,(10),IF(E17>27,(9),IF(E17>21,(8),(IF(E17>15,(7),IF(E17>11,(6),IF(E17>9,(5),IF(E17>7,(4),IF(E17>5,(3),IF(E17>4,(2),IF(E17>0,(1),"-"))))))))))) -> 5 | F26: =IF(F17>34,(10),IF(F17>27,(9),IF(F17>21,(8),(IF(F17>15,(7),IF(F17>11,(6),IF(F17>9,(5),IF(F17>7,(4),IF(F17>5,(3),IF(F17>4,(2),IF(F17>0,(1),"-"))))))))))) -> 1 | G26: =IF(G17>34,(10),IF(G17>27,(9),IF(G17>21,(8),(IF(G17>15,(7),IF(G17>11,(6),IF(G17>9,(5),IF(G17>7,(4),IF(G17>5,(3),IF(G17>4,(2),IF(G17>0,(1),"-"))))))))))) -> - | H26: =IF(H17>34,(10),IF(H17>27,(9),IF(H17>21,(8),(IF(H17>15,(7),IF(H17>11,(6),IF(H17>9,(5),IF(H17>7,(4),IF(H17>5,(3),IF(H17>4,(2),IF(H17>0,(1),"-"))))))))))) -> 3 | I26: =IF(I17>34,(10),IF(I17>27,(9),IF(I17>21,(8),(IF(I17>15,(7),IF(I17>11,(6),IF(I17>9,(5),IF(I17>7,(4),IF(I17>5,(3),IF(I17>4,(2),IF(I17>0,(1),"-"))))))))))) -> - | J26: =IF(J17>34,(10),IF(J17>27,(9),IF(J17>21,(8),(IF(J17>15,(7),IF(J17>11,(6),IF(J17>9,(5),IF(J17>7,(4),IF(J17>5,(3),IF(J17>4,(2),IF(J17>0,(1),"-"))))))))))) -> 6
A27: 26 | B27: =IF(CUESTIONARIO!C27="1. Totalmente en desacuerdo",(1),IF(CUESTIONARIO!C27="2. En desacuerdo",(2),IF(CUESTIONARIO!C27="3. Es difícil decidir",(3),IF(CUESTIONARIO!C27="4. De acuerdo",(4),IF(CUESTIONARIO!C27="5. Totalmente de acuerdo",(5)))))) -> 2 | D27: CONVENCIONAL | E27: =IF(E18>34,(10),IF(E18>27,(9),IF(E18>21,(8),(IF(E18>15,(7),IF(E18>11,(6),IF(E18>9,(5),IF(E18>7,(4),IF(E18>5,(3),IF(E18>4,(2),IF(E18>0,(1),"-"))))))))))) -> - | F27: =IF(F18>34,(10),IF(F18>27,(9),IF(F18>21,(8),(IF(F18>15,(7),IF(F18>11,(6),IF(F18>9,(5),IF(F18>7,(4),IF(F18>5,(3),IF(F18>4,(2),IF(F18>0,(1),"-"))))))))))) -> - | G27: =IF(G18>34,(10),IF(G18>27,(9),IF(G18>21,(8),(IF(G18>15,(7),IF(G18>11,(6),IF(G18>9,(5),IF(G18>7,(4),IF(G18>5,(3),IF(G18>4,(2),IF(G18>0,(1),"-"))))))))))) -> - | H27: =IF(H18>34,(10),IF(H18>27,(9),IF(H18>21,(8),(IF(H18>15,(7),IF(H18>11,(6),IF(H18>9,(5),IF(H18>7,(4),IF(H18>5,(3),IF(H18>4,(2),IF(H18>0,(1),"-"))))))))))) -> - | I27: =IF(I18>34,(10),IF(I18>27,(9),IF(I18>21,(8),(IF(I18>15,(7),IF(I18>11,(6),IF(I18>9,(5),IF(I18>7,(4),IF(I18>5,(3),IF(I18>4,(2),IF(I18>0,(1),"-"))))))))))) -> - | J27: =IF(J18>34,(10),IF(J18>27,(9),IF(J18>21,(8),(IF(J18>15,(7),IF(J18>11,(6),IF(J18>9,(5),IF(J18>7,(4),IF(J18>5,(3),IF(J18>4,(2),IF(J18>0,(1),"-"))))))))))) -> -
A28: 27 | B28: =IF(CUESTIONARIO!C28="1. Totalmente en desacuerdo",(1),IF(CUESTIONARIO!C28="2. En desacuerdo",(2),IF(CUESTIONARIO!C28="3. Es difícil decidir",(3),IF(CUESTIONARIO!C28="4. De acuerdo",(4),IF(CUESTIONARIO!C28="5. Totalmente de acuerdo",(5)))))) -> 2
A29: 28 | B29: =IF(CUESTIONARIO!C29="1. Totalmente en desacuerdo",(1),IF(CUESTIONARIO!C29="2. En desacuerdo",(2),IF(CUESTIONARIO!C29="3. Es difícil decidir",(3),IF(CUESTIONARIO!C29="4. De acuerdo",(4),IF(CUESTIONARIO!C29="5. Totalmente de acuerdo",(5)))))) -> 3 | D29: STEN DIFERENCIACIÓN HOMBRES
A30: 29 | B30: =IF(CUESTIONARIO!C30="1. Totalmente en desacuerdo",(1),IF(CUESTIONARIO!C30="2. En desacuerdo",(2),IF(CUESTIONARIO!C30="3. Es difícil decidir",(3),IF(CUESTIONARIO!C30="4. De acuerdo",(4),IF(CUESTIONARIO!C30="5. Totalmente de acuerdo",(5)))))) -> 2 | E30: REALISTA | F30: INVESTIGADORA | G30: ARTISTICA | H30: SOCIAL | I30: EMPRENDEDORA | J30: CONVENCIONAL
A31: 30 | B31: =IF(CUESTIONARIO!C31="1. Totalmente en desacuerdo",(1),IF(CUESTIONARIO!C31="2. En desacuerdo",(2),IF(CUESTIONARIO!C31="3. Es difícil decidir",(3),IF(CUESTIONARIO!C31="4. De acuerdo",(4),IF(CUESTIONARIO!C31="5. Totalmente de acuerdo",(5)))))) -> 4 | D31: REALISTA | E31: =IF(E13>30,(10),IF(E13>23,(9),IF(E13>18,(8),(IF(E13>13,(7),IF(E13>10,(6),IF(E13>7,(5),IF(E13>5,(4),IF(E13>4,(3),IF(E13>3,(2),IF(E13>0,(1),"-"))))))))))) -> - | F31: =IF(F13>30,(10),IF(F13>23,(9),IF(F13>18,(8),(IF(F13>13,(7),IF(F13>10,(6),IF(F13>7,(5),IF(F13>5,(4),IF(F13>4,(3),IF(F13>3,(2),IF(F13>0,(1),"-"))))))))))) -> - | G31: =IF(G13>30,(10),IF(G13>23,(9),IF(G13>18,(8),(IF(G13>13,(7),IF(G13>10,(6),IF(G13>7,(5),IF(G13>5,(4),IF(G13>4,(3),IF(G13>3,(2),IF(G13>0,(1),"-"))))))))))) -> - | H31: =IF(H13>30,(10),IF(H13>23,(9),IF(H13>18,(8),(IF(H13>13,(7),IF(H13>10,(6),IF(H13>7,(5),IF(H13>5,(4),IF(H13>4,(3),IF(H13>3,(2),IF(H13>0,(1),"-"))))))))))) -> - | I31: =IF(I13>30,(10),IF(I13>23,(9),IF(I13>18,(8),(IF(I13>13,(7),IF(I13>10,(6),IF(I13>7,(5),IF(I13>5,(4),IF(I13>4,(3),IF(I13>3,(2),IF(I13>0,(1),"-"))))))))))) -> - | J31: =IF(J13>30,(10),IF(J13>23,(9),IF(J13>18,(8),(IF(J13>13,(7),IF(J13>10,(6),IF(J13>7,(5),IF(J13>5,(4),IF(J13>4,(3),IF(J13>3,(2),IF(J13>0,(1),"-"))))))))))) -> 1
A32: 31 | B32: =IF(CUESTIONARIO!C32="1. Totalmente en desacuerdo",(1),IF(CUESTIONARIO!C32="2. En desacuerdo",(2),IF(CUESTIONARIO!C32="3. Es difícil decidir",(3),IF(CUESTIONARIO!C32="4. De acuerdo",(4),IF(CUESTIONARIO!C32="5. Totalmente de acuerdo",(5)))))) -> 4 | D32: INVESTIGADORA | E32: =IF(E14>30,(10),IF(E14>23,(9),IF(E14>18,(8),(IF(E14>13,(7),IF(E14>10,(6),IF(E14>7,(5),IF(E14>5,(4),IF(E14>4,(3),IF(E14>3,(2),IF(E14>0,(1),"-"))))))))))) -> 4 | F32: =IF(F14>30,(10),IF(F14>23,(9),IF(F14>18,(8),(IF(F14>13,(7),IF(F14>10,(6),IF(F14>7,(5),IF(F14>5,(4),IF(F14>4,(3),IF(F14>3,(2),IF(F14>0,(1),"-"))))))))))) -> - | G32: =IF(G14>30,(10),IF(G14>23,(9),IF(G14>18,(8),(IF(G14>13,(7),IF(G14>10,(6),IF(G14>7,(5),IF(G14>5,(4),IF(G14>4,(3),IF(G14>3,(2),IF(G14>0,(1),"-"))))))))))) -> - | H32: =IF(H14>30,(10),IF(H14>23,(9),IF(H14>18,(8),(IF(H14>13,(7),IF(H14>10,(6),IF(H14>7,(5),IF(H14>5,(4),IF(H14>4,(3),IF(H14>3,(2),IF(H14>0,(1),"-"))))))))))) -> 1 | I32: =IF(I14>30,(10),IF(I14>23,(9),IF(I14>18,(8),(IF(I14>13,(7),IF(I14>10,(6),IF(I14>7,(5),IF(I14>5,(4),IF(I14>4,(3),IF(I14>3,(2),IF(I14>0,(1),"-"))))))))))) -> - | J32: =IF(J14>30,(10),IF(J14>23,(9),IF(J14>18,(8),(IF(J14>13,(7),IF(J14>10,(6),IF(J14>7,(5),IF(J14>5,(4),IF(J14>4,(3),IF(J14>3,(2),IF(J14>0,(1),"-"))))))))))) -> 5
A33: 32 | B33: =IF(CUESTIONARIO!C33="1. Totalmente en desacuerdo",(1),IF(CUESTIONARIO!C33="2. En desacuerdo",(2),IF(CUESTIONARIO!C33="3. Es difícil decidir",(3),IF(CUESTIONARIO!C33="4. De acuerdo",(4),IF(CUESTIONARIO!C33="5. Totalmente de acuerdo",(5)))))) -> 2 | D33: ARTISTICA | E33: =IF(E15>30,(10),IF(E15>23,(9),IF(E15>18,(8),(IF(E15>13,(7),IF(E15>10,(6),IF(E15>7,(5),IF(E15>5,(4),IF(E15>4,(3),IF(E15>3,(2),IF(E15>0,(1),"-"))))))))))) -> 5 | F33: =IF(F15>30,(10),IF(F15>23,(9),IF(F15>18,(8),(IF(F15>13,(7),IF(F15>10,(6),IF(F15>7,(5),IF(F15>5,(4),IF(F15>4,(3),IF(F15>3,(2),IF(F15>0,(1),"-"))))))))))) -> 1 | G33: =IF(G15>30,(10),IF(G15>23,(9),IF(G15>18,(8),(IF(G15>13,(7),IF(G15>10,(6),IF(G15>7,(5),IF(G15>5,(4),IF(G15>4,(3),IF(G15>3,(2),IF(G15>0,(1),"-"))))))))))) -> - | H33: =IF(H15>30,(10),IF(H15>23,(9),IF(H15>18,(8),(IF(H15>13,(7),IF(H15>10,(6),IF(H15>7,(5),IF(H15>5,(4),IF(H15>4,(3),IF(H15>3,(2),IF(H15>0,(1),"-"))))))))))) -> 4 | I33: =IF(I15>30,(10),IF(I15>23,(9),IF(I15>18,(8),(IF(I15>13,(7),IF(I15>10,(6),IF(I15>7,(5),IF(I15>5,(4),IF(I15>4,(3),IF(I15>3,(2),IF(I15>0,(1),"-"))))))))))) -> - | J33: =IF(J15>30,(10),IF(J15>23,(9),IF(J15>18,(8),(IF(J15>13,(7),IF(J15>10,(6),IF(J15>7,(5),IF(J15>5,(4),IF(J15>4,(3),IF(J15>3,(2),IF(J15>0,(1),"-"))))))))))) -> 6
A34: 33 | B34: =IF(CUESTIONARIO!C34="1. Totalmente en desacuerdo",(1),IF(CUESTIONARIO!C34="2. En desacuerdo",(2),IF(CUESTIONARIO!C34="3. Es difícil decidir",(3),IF(CUESTIONARIO!C34="4. De acuerdo",(4),IF(CUESTIONARIO!C34="5. Totalmente de acuerdo",(5)))))) -> 2 | D34: SOCIAL | E34: =IF(E16>30,(10),IF(E16>23,(9),IF(E16>18,(8),(IF(E16>13,(7),IF(E16>10,(6),IF(E16>7,(5),IF(E16>5,(4),IF(E16>4,(3),IF(E16>3,(2),IF(E16>0,(1),"-"))))))))))) -> 2 | F34: =IF(F16>30,(10),IF(F16>23,(9),IF(F16>18,(8),(IF(F16>13,(7),IF(F16>10,(6),IF(F16>7,(5),IF(F16>5,(4),IF(F16>4,(3),IF(F16>3,(2),IF(F16>0,(1),"-"))))))))))) -> - | G34: =IF(G16>30,(10),IF(G16>23,(9),IF(G16>18,(8),(IF(G16>13,(7),IF(G16>10,(6),IF(G16>7,(5),IF(G16>5,(4),IF(G16>4,(3),IF(G16>3,(2),IF(G16>0,(1),"-"))))))))))) -> - | H34: =IF(H16>30,(10),IF(H16>23,(9),IF(H16>18,(8),(IF(H16>13,(7),IF(H16>10,(6),IF(H16>7,(5),IF(H16>5,(4),IF(H16>4,(3),IF(H16>3,(2),IF(H16>0,(1),"-"))))))))))) -> - | I34: =IF(I16>30,(10),IF(I16>23,(9),IF(I16>18,(8),(IF(I16>13,(7),IF(I16>10,(6),IF(I16>7,(5),IF(I16>5,(4),IF(I16>4,(3),IF(I16>3,(2),IF(I16>0,(1),"-"))))))))))) -> - | J34: =IF(J16>30,(10),IF(J16>23,(9),IF(J16>18,(8),(IF(J16>13,(7),IF(J16>10,(6),IF(J16>7,(5),IF(J16>5,(4),IF(J16>4,(3),IF(J16>3,(2),IF(J16>0,(1),"-"))))))))))) -> 4
A35: 34 | B35: =IF(CUESTIONARIO!C35="1. Totalmente en desacuerdo",(1),IF(CUESTIONARIO!C35="2. En desacuerdo",(2),IF(CUESTIONARIO!C35="3. Es difícil decidir",(3),IF(CUESTIONARIO!C35="4. De acuerdo",(4),IF(CUESTIONARIO!C35="5. Totalmente de acuerdo",(5)))))) -> 2 | D35: EMPRENDEDORA | E35: =IF(E17>30,(10),IF(E17>23,(9),IF(E17>18,(8),(IF(E17>13,(7),IF(E17>10,(6),IF(E17>7,(5),IF(E17>5,(4),IF(E17>4,(3),IF(E17>3,(2),IF(E17>0,(1),"-"))))))))))) -> 5 | F35: =IF(F17>30,(10),IF(F17>23,(9),IF(F17>18,(8),(IF(F17>13,(7),IF(F17>10,(6),IF(F17>7,(5),IF(F17>5,(4),IF(F17>4,(3),IF(F17>3,(2),IF(F17>0,(1),"-"))))))))))) -> 1 | G35: =IF(G17>30,(10),IF(G17>23,(9),IF(G17>18,(8),(IF(G17>13,(7),IF(G17>10,(6),IF(G17>7,(5),IF(G17>5,(4),IF(G17>4,(3),IF(G17>3,(2),IF(G17>0,(1),"-"))))))))))) -> - | H35: =IF(H17>30,(10),IF(H17>23,(9),IF(H17>18,(8),(IF(H17>13,(7),IF(H17>10,(6),IF(H17>7,(5),IF(H17>5,(4),IF(H17>4,(3),IF(H17>3,(2),IF(H17>0,(1),"-"))))))))))) -> 4 | I35: =IF(I17>30,(10),IF(I17>23,(9),IF(I17>18,(8),(IF(I17>13,(7),IF(I17>10,(6),IF(I17>7,(5),IF(I17>5,(4),IF(I17>4,(3),IF(I17>3,(2),IF(I17>0,(1),"-"))))))))))) -> - | J35: =IF(J17>30,(10),IF(J17>23,(9),IF(J17>18,(8),(IF(J17>13,(7),IF(J17>10,(6),IF(J17>7,(5),IF(J17>5,(4),IF(J17>4,(3),IF(J17>3,(2),IF(J17>0,(1),"-"))))))))))) -> 6
A36: 35 | B36: =IF(CUESTIONARIO!C36="1. Totalmente en desacuerdo",(1),IF(CUESTIONARIO!C36="2. En desacuerdo",(2),IF(CUESTIONARIO!C36="3. Es difícil decidir",(3),IF(CUESTIONARIO!C36="4. De acuerdo",(4),IF(CUESTIONARIO!C36="5. Totalmente de acuerdo",(5)))))) -> 3 | D36: CONVENCIONAL | E36: =IF(E18>30,(10),IF(E18>23,(9),IF(E18>18,(8),(IF(E18>13,(7),IF(E18>10,(6),IF(E18>7,(5),IF(E18>5,(4),IF(E18>4,(3),IF(E18>3,(2),IF(E18>0,(1),"-"))))))))))) -> - | F36: =IF(F18>30,(10),IF(F18>23,(9),IF(F18>18,(8),(IF(F18>13,(7),IF(F18>10,(6),IF(F18>7,(5),IF(F18>5,(4),IF(F18>4,(3),IF(F18>3,(2),IF(F18>0,(1),"-"))))))))))) -> - | G36: =IF(G18>30,(10),IF(G18>23,(9),IF(G18>18,(8),(IF(G18>13,(7),IF(G18>10,(6),IF(G18>7,(5),IF(G18>5,(4),IF(G18>4,(3),IF(G18>3,(2),IF(G18>0,(1),"-"))))))))))) -> - | H36: =IF(H18>30,(10),IF(H18>23,(9),IF(H18>18,(8),(IF(H18>13,(7),IF(H18>10,(6),IF(H18>7,(5),IF(H18>5,(4),IF(H18>4,(3),IF(H18>3,(2),IF(H18>0,(1),"-"))))))))))) -> - | I36: =IF(I18>30,(10),IF(I18>23,(9),IF(I18>18,(8),(IF(I18>13,(7),IF(I18>10,(6),IF(I18>7,(5),IF(I18>5,(4),IF(I18>4,(3),IF(I18>3,(2),IF(I18>0,(1),"-"))))))))))) -> - | J36: =IF(J18>30,(10),IF(J18>23,(9),IF(J18>18,(8),(IF(J18>13,(7),IF(J18>10,(6),IF(J18>7,(5),IF(J18>5,(4),IF(J18>4,(3),IF(J18>3,(2),IF(J18>0,(1),"-"))))))))))) -> -
A37: 36 | B37: =IF(CUESTIONARIO!C37="1. Totalmente en desacuerdo",(1),IF(CUESTIONARIO!C37="2. En desacuerdo",(2),IF(CUESTIONARIO!C37="3. Es difícil decidir",(3),IF(CUESTIONARIO!C37="4. De acuerdo",(4),IF(CUESTIONARIO!C37="5. Totalmente de acuerdo",(5)))))) -> 2
A38: 37 | B38: =IF(CUESTIONARIO!C38="1. Totalmente en desacuerdo",(1),IF(CUESTIONARIO!C38="2. En desacuerdo",(2),IF(CUESTIONARIO!C38="3. Es difícil decidir",(3),IF(CUESTIONARIO!C38="4. De acuerdo",(4),IF(CUESTIONARIO!C38="5. Totalmente de acuerdo",(5)))))) -> 4
A39: 38 | B39: =IF(CUESTIONARIO!C39="1. Totalmente en desacuerdo",(1),IF(CUESTIONARIO!C39="2. En desacuerdo",(2),IF(CUESTIONARIO!C39="3. Es difícil decidir",(3),IF(CUESTIONARIO!C39="4. De acuerdo",(4),IF(CUESTIONARIO!C39="5. Totalmente de acuerdo",(5)))))) -> 2 | D39: INTERPRETACIÓN DIFERENCIACIÓN MUJERES
A40: 39 | B40: =IF(CUESTIONARIO!C40="1. Totalmente en desacuerdo",(1),IF(CUESTIONARIO!C40="2. En desacuerdo",(2),IF(CUESTIONARIO!C40="3. Es difícil decidir",(3),IF(CUESTIONARIO!C40="4. De acuerdo",(4),IF(CUESTIONARIO!C40="5. Totalmente de acuerdo",(5)))))) -> 2 | E40: REALISTA | F40: INVESTIGADORA | G40: ARTISTICA | H40: SOCIAL | I40: EMPRENDEDORA | J40: CONVENCIONAL
...

Sheet RESULTADOS
B2: RESULTADOS
B4: I. DATOS PERSONALES
B6: NOMBRES: | C6: =INSTRUCCIONES!D32 -> JARAMILLO CAICEDO | E6: =INSTRUCCIONES!D33 -> RUBÉN PATRICIO
B7: CURSO: | C7: =INSTRUCCIONES!D34 -> 3º BGU | D7: =INSTRUCCIONES!D35 -> A
B8: FECHA: | C8: =INSTRUCCIONES!D38 -> 44194
B10: II. ENCUESTA
G12: TIPO VOCACIONAL
B13: CARRERAS PREFERIDAS: | D13: 1) | E13: =ENCUESTA!C4 -> MEDICINA
D14: 2) | E14: =ENCUESTA!C5 -> SISTEMAS
D15: 3) | E15: =ENCUESTA!C6 -> ELECTRICIDAD
B19: III. ANÁLISIS GLOBAL DE RESULTADOS DEL IPPJ
B23: PUNTAJE
B24: REALISTA | C24: =fórmulas!I2 -> 3
B25: INVESTIGADORA | C25: =fórmulas!I3 -> 2
B26: ARTISTICA | C26: =fórmulas!I4 -> 2
B27: SOCIAL | C27: =fórmulas!I5 -> 4
B28: EMPRENDEDORA | C28: =fórmulas!I6 -> 1
B29: CONVENCIONAL | C29: =fórmulas!I7 -> 3
B33: INTENSIDAD
B34: NIVEL | C34: =IF(fórmulas!I8>6,"Alta",IF(fórmulas!I8>4,"Media",IF(fórmulas!I8>0,"Baja"))) -> Baja
B38: DIFERENCIACIÓN
C39: REALISTA | D39: INVESTIGADORA | E39: ARTISTICA | F39: SOCIAL | G39: EMPRENDEDORA | H39: CONVENCIONAL
B40: REALISTA | C40: =IF(INSTRUCCIONES!D37="FEMENINO",fórmulas!E41,IF(INSTRUCCIONES!D37="MASCULINO",fórmulas!E50)) -> - | D40: =IF(INSTRUCCIONES!D37="FEMENINO",fórmulas!F41,IF(INSTRUCCIONES!D37="MASCULINO",fórmulas!F50)) -> - | E40: =IF(INSTRUCCIONES!D37="FEMENINO",fórmulas!G41,IF(INSTRUCCIONES!D37="MASCULINO",fórmulas!G50)) -> - | F40: =IF(INSTRUCCIONES!D37="FEMENINO",fórmulas!H41,IF(INSTRUCCIONES!D37="MASCULINO",fórmulas!H50)) -> - | G40: =IF(INSTRUCCIONES!D37="FEMENINO",fórmulas!I41,IF(INSTRUCCIONES!D37="MASCULINO",fórmulas!I50)) -> - | H40: =IF(INSTRUCCIONES!D37="FEMENINO",fórmulas!J41,IF(INSTRUCCIONES!D37="MASCULINO",fórmulas!J50)) -> Baja
B41: INVESTIGADORA | C41: =IF(INSTRUCCIONES!D37="FEMENINO",fórmulas!E42,IF(INSTRUCCIONES!D37="MASCULINO",fórmulas!E51)) -> Baja | D41: =IF(INSTRUCCIONES!D37="FEMENINO",fórmulas!F42,IF(INSTRUCCIONES!D37="MASCULINO",fórmulas!F51)) -> - | E41: =IF(INSTRUCCIONES!D37="FEMENINO",fórmulas!G42,IF(INSTRUCCIONES!D37="MASCULINO",fórmulas!G51)) -> - | F41: =IF(INSTRUCCIONES!D37="FEMENINO",fórmulas!H42,IF(INSTRUCCIONES!D37="MASCULINO",fórmulas!H51)) -> Baja | G41: =IF(INSTRUCCIONES!D37="FEMENINO",fórmulas!I42,IF(INSTRUCCIONES!D37="MASCULINO",fórmulas!I51)) -> - | H41: =IF(INSTRUCCIONES!D37="FEMENINO",fórmulas!J42,IF(INSTRUCCIONES!D37="MASCULINO",fórmulas!J51)) -> Media
B42: ARTISTICA | C42: =IF(INSTRUCCIONES!D37="FEMENINO",fórmulas!E43,IF(INSTRUCCIONES!D37="MASCULINO",fórmulas!E52)) -> Media | D42: =IF(INSTRUCCIONES!D37="FEMENINO",fórmulas!F43,IF(INSTRUCCIONES!D37="MASCULINO",fórmulas!F52)) -> Baja | E42: =IF(INSTRUCCIONES!D37="FEMENINO",fórmulas!G43,IF(INSTRUCCIONES!D37="MASCULINO",fórmulas!G52)) -> - | F42: =IF(INSTRUCCIONES!D37="FEMENINO",fórmulas!H43,IF(INSTRUCCIONES!D37="MASCULINO",fórmulas!H52)) -> Baja | G42: =IF(INSTRUCCIONES!D37="FEMENINO",fórmulas!I43,IF(INSTRUCCIONES!D37="MASCULINO",fórmulas!I52)) -> - | H42: =IF(INSTRUCCIONES!D37="FEMENINO",fórmulas!J43,IF(INSTRUCCIONES!D37="MASCULINO",fórmulas!J52)) -> Media
B43: SOCIAL | C43: =IF(INSTRUCCIONES!D37="FEMENINO",fórmulas!E44,IF(INSTRUCCIONES!D37="MASCULINO",fórmulas!E53)) -> Baja | D43: =IF(INSTRUCCIONES!D37="FEMENINO",fórmulas!F44,IF(INSTRUCCIONES!D37="MASCULINO",fórmulas!F53)) -> - | E43: =IF(INSTRUCCIONES!D37="FEMENINO",fórmulas!G44,IF(INSTRUCCIONES!D37="MASCULINO",fórmulas!G53)) -> - | F43: =IF(INSTRUCCIONES!D37="FEMENINO",fórmulas!H44,IF(INSTRUCCIONES!D37="MASCULINO",fórmulas!H53)) -> - | G43: =IF(INSTRUCCIONES!D37="FEMENINO",fórmulas!I44,IF(INSTRUCCIONES!D37="MASCULINO",fórmulas!I53)) -> - | H43: =IF(INSTRUCCIONES!D37="FEMENINO",fórmulas!J44,IF(INSTRUCCIONES!D37="MASCULINO",fórmulas!J53)) -> Baja
B44: EMPRENDEDORA | C44: =IF(INSTRUCCIONES!D37="FEMENINO",fórmulas!E45,IF(INSTRUCCIONES!D37="MASCULINO",fórmulas!E54)) -> Media | D44: =IF(INSTRUCCIONES!D37="FEMENINO",fórmulas!F45,IF(INSTRUCCIONES!D37="MASCULINO",fórmulas!F54)) -> Baja | E44: =IF(INSTRUCCIONES!D37="FEMENINO",fórmulas!G45,IF(INSTRUCCIONES!D37="MASCULINO",fórmulas!G54)) -> - | F44: =IF(INSTRUCCIONES!D37="FEMENINO",fórmulas!H45,IF(INSTRUCCIONES!D37="MASCULINO",fórmulas!H54)) -> Baja | G44: =IF(INSTRUCCIONES!D37="FEMENINO",fórmulas!I45,IF(INSTRUCCIONES!D37="MASCULINO",fórmulas!I54)) -> - | H44: =IF(INSTRUCCIONES!D37="FEMENINO",fórmulas!J45,IF(INSTRUCCIONES!D37="MASCULINO",fórmulas!J54)) -> Media
B45: CONVENCIONAL | C45: =IF(INSTRUCCIONES!D37="FEMENINO",fórmulas!E46,IF(INSTRUCCIONES!D37="MASCULINO",fórmulas!E55)) -> - | D45: =IF(INSTRUCCIONES!D37="FEMENINO",fórmulas!F46,IF(INSTRUCCIONES!D37="MASCULINO",fórmulas!F55)) -> - | E45: =IF(INSTRUCCIONES!D37="FEMENINO",fórmulas!G46,IF(INSTRUCCIONES!D37="MASCULINO",fórmulas!G55)) -> - | F45: =IF(INSTRUCCIONES!D37="FEMENINO",fórmulas!H46,IF(INSTRUCCIONES!D37="MASCULINO",fórmulas!H55)) -> - | G45: =IF(INSTRUCCIONES!D37="FEMENINO",fórmulas!I46,IF(INSTRUCCIONES!D37="MASCULINO",fórmulas!I55)) -> - | H45: =IF(INSTRUCCIONES!D37="FEMENINO",fórmulas!J46,IF(INSTRUCCIONES!D37="MASCULINO",fórmulas!J55)) -> -
B48: CONSISTENCIA | F48: RECOMENDACIONES
B49: REALISTA - INVESTIGADORA | D49: =IF(INSTRUCCIONES!D37="FEMENINO",fórmulas!O2,IF(INSTRUCCIONES!D37="MASCULINO",fórmulas!P2)) -> Alta
B50: INVESTIGADORA - ARTISTICA | D50: =IF(INSTRUCCIONES!D37="FEMENINO",fórmulas!O3,IF(INSTRUCCIONES!D37="MASCULINO",fórmulas!P3)) -> Alta
B51: ARTISTICA - SOCIAL | D51: =IF(INSTRUCCIONES!D37="FEMENINO",fórmulas!O4,IF(INSTRUCCIONES!D37="MASCULINO",fórmulas!P4)) -> Alta
B52: SOCIAL - EMPRENDEDORA | D52: =IF(INSTRUCCIONES!D37="FEMENINO",fórmulas!O5,IF(INSTRUCCIONES!D37="MASCULINO",fórmulas!P5)) -> Alta
B53: EMPRENDEDORA - CONVENCIONAL | D53: =IF(INSTRUCCIONES!D37="FEMENINO",fórmulas!O6,IF(INSTRUCCIONES!D37="MASCULINO",fórmulas!P6)) -> Alta
B54: CONVENCIONAL - REALISTA | D54: =IF(INSTRUCCIONES!D37="FEMENINO",fórmulas!O7,IF(INSTRUCCIONES!D37="MASCULINO",fórmulas!P7)) -> Alta
B56: CONGRUENCIA
B57: CARRERA PREFERIDA 1
B58: CARRERA PREFERIDA 2
B59: CARRERA PREFERIDA 3
B63: IV. DATOS PROFESIONAL DECE
...
